Workbook

Sheet Sheet1
C1: Student Interest | F1: Student Attitude | L1: Student Study habits | R1: Teacher Teaching style | W1: Teacher Expectations and support | AA1: Teacher Availability and communication
A2: Grade | B2: CLASS | C2: I listen attentively | D2: Actively participate | E2: I want good grades | F2: Struggle to understand | G2: Math scares me | H2: Don't like or enjoy math | I2: mind goes blank | J2: I feel insecure | K2: Makes me uncomfortable, restless, impatient | L2: I do assignments regularly | M2: I put more effort in difficult assignments | N2: I spend time studying maths | O2: I study and prepare for tests | P2: I put in effort to improve my performance | Q2: Studies come first in my life | R2: Clearly explains new concepts | S2: Encourages us to ask questions | T2: Explains concepts in different ways | U2: Provides real-world applications | V2: Makes me feel ocmfortable to make mistakes | W2: Provides extra help to struggling students | X2: Sets clear explectations | Y2: Provides constructive feedback | Z2: Believes we all can perform well | AA2: Is available outside class time | AB2: Provides clear instructions for assignments | AC2: Explains progress in areas we are lacking.
B3: 1 | C3: 4 | D3: 5 | E3: 4 | F3: 4 | G3: 4 | H3: 4 | I3: 1 | J3: 2 | K3: 1 | L3: 4 | M3: 4 | N3: 4 | O3: 4 | P3: 4 | Q3: 4 | R3: 4 | S3: 4 | T3: 4 | U3: 1 | V3: 4 | W3: 5 | X3: 2 | Y3: 4 | Z3: 5 | AA3: 4 | AB3: 4 | AC3: 5 | AD3: =AVERAGE(R3:V3) -> 3.4
B4: 1 | C4: 5 | D4: 4 | E4: 5 | F4: 5 | G4: 4 | H4: 3 | I4: 2 | J4: 1 | K4: 1 | L4: 4 | M4: 5 | N4: 3 | O4: 4 | P4: 5 | Q4: 5 | R4: 5 | S4: 5 | T4: 3 | U4: 2 | V4: 5 | W4: 4 | X4: 3 | Y4: 5 | Z4: 5 | AA4: 4 | AB4: 5 | AC4: 4 | AD4: =AVERAGE(R4:V4) -> 4
B5: 1 | C5: 4 | D5: 3 | E5: 4 | F5: 4 | G5: 4 | H5: 1 | I5: 2 | J5: 1 | K5: 1 | L5: 3 | M5: 3 | N5: 2 | O5: 3 | P5: 4 | Q5: 5 | R5: 4 | S5: 5 | T5: 5 | U5: 3
B6: 1 | C6: 4 | D6: 3 | E6: 4 | F6: 4 | G6: 4 | H6: 1 | I6: 1 | J6: 1 | K6: 1 | L6: 4 | M6: 4 | N6: 3 | O6: 4 | P6: 4 | Q6: 4 | R6: 5 | S6: 5 | T6: 4 | U6: 5 | V6: 1 | W6: 5 | X6: 5 | Y6: 5 | Z6: 5 | AA6: 5 | AB6: 5 | AC6: 5 | AD6: =AVERAGE(R6:V6) -> 4
B7: 1 | C7: 5 | D7: 3 | E7: 4 | F7: 4 | G7: 4 | H7: 1 | I7: 3 | J7: 1 | K7: 2 | L7: 5 | M7: 4 | N7: 2 | O7: 4 | P7: 5 | Q7: 4 | R7: 4 | S7: 5 | T7: 5 | U7: 5 | V7: 1 | W7: 5 | X7: 5 | Y7: 5 | Z7: 5 | AA7: 4 | AB7: 5 | AC7: 5
B8: 1 | C8: 4 | D8: 2 | E8: 5 | F8: 4 | G8: 4 | H8: 2 | I8: 2 | J8: 2 | K8: 2 | L8: 4 | M8: 5 | N8: 3 | O8: 5 | P8: 4 | Q8: 3 | R8: 3 | S8: 5 | T8: 5 | U8: 5 | V8: 2 | W8: 5 | X8: 5 | Y8: 4 | Z8: 5 | AA8: 4 | AB8: 5 | AC8: 5
B9: 1 | C9: 4 | D9: 3 | E9: 5 | F9: 3 | G9: 4 | H9: 1 | I9: 2 | J9: 3 | K9: 3 | L9: 4 | M9: 3 | N9: 2 | O9: 3 | P9: 5 | Q9: 4 | R9: 2 | S9: 5 | T9: 5 | U9: 5 | V9: 2 | W9: 3 | X9: 2 | Y9: 3 | Z9: 5 | AA9: 5 | AB9: 5 | AC9: 5 | AD9: =AVERAGE(R9:V9) -> 3.8
B10: 1 | C10: 5 | D10: 3 | E10: 4 | F10: 3 | G10: 5 | H10: 2 | I10: 1 | J10: 2 | K10: 2 | L10: 4 | M10: 3 | N10: 2 | O10: 3 | P10: 4 | Q10: 5 | R10: 1 | S10: 4 | T10: 4 | U10: 5 | V10: 3 | W10: 3 | X10: 2 | Y10: 3 | Z10: 4 | AA10: 4 | AB10: 5 | AC10: 5
A11: D- | B11: 1 | C11: 4 | D11: 2 | E11: 5 | F11: 5 | G11: 4 | H11: 1 | I11: 2 | J11: 1 | K11: 1 | L11: 4 | M11: 5 | N11: 5 | O11: 5 | P11: 5 | Q11: 4 | R11: 5 | S11: 5 | T11: 5 | U11: 5 | V11: 5 | W11: 5 | X11: 5 | Y11: 5 | Z11: 5 | AA11: 5 | AB11: 5 | AC11: 5 | AD11: =AVERAGE(R11:V11) -> 5
B12: 1 | C12: 5 | D12: 3 | E12: 5 | F12: 5 | G12: 4 | H12: 1 | I12: 2 | J12: 2 | K12: 2 | L12: 4 | M12: 5 | N12: 4 | O12: 5 | P12: 5 | Q12: 4 | R12: 5 | S12: 5 | T12: 5 | U12: 5 | V12: 5 | W12: 5 | X12: 5 | Y12: 4 | Z12: 5 | AA12: 5 | AB12: 5 | AC12: 5
B13: 1 | C13: 4 | D13: 2 | E13: 4 | F13: 5 | G13: 4 | H13: 1 | I13: 1 | J13: 1 | K13: 1 | L13: 4 | M13: 5 | N13: 4 | O13: 4 | P13: 4 | Q13: 4 | R13: 5 | S13: 5 | T13: 5 | U13: 5 | V13: 4 | W13: 5 | X13: 4 | Y13: 5 | Z13: 5 | AA13: 5 | AB13: 5 | AC13: 5
B14: 1 | C14: 4 | D14: 4 | E14: 4 | F14: 4 | G14: 1 | H14: 1 | I14: 1 | J14: 1 | K14: 1 | L14: 4 | M14: 4 | N14: 4 | O14: 4 | P14: 4 | Q14: 4 | R14: 4 | S14: 5 | T14: 5 | U14: 4 | V14: 1 | W14: 5 | X14: 5 | Y14: 4 | Z14: 5 | AA14: 5 | AB14: 5 | AC14: 5 | AD14: =AVERAGE(R14:V14) -> 3.8
A15: c- | B15: 3 | C15: 4 | D15: 3 | E15: 5 | F15: 2 | G15: 3 | H15: 1 | I15: 3 | J15: 3 | K15: 1 | L15: 4 | M15: 4 | N15: 4 | O15: 4 | P15: 4 | Q15: 4 | R15: 5 | S15: 5 | T15: 5 | U15: 5 | V15: 1 | W15: 1 | X15: 2 | Y15: 2 | Z15: 2 | AA15: 3 | AB15: 2 | AC15: 5 | AD15: =AVERAGE(R15:V15) -> 4.2
B16: 3 | C16: 5 | D16: 2 | E16: 5 | F16: 3 | G16: 3 | H16: 1 | I16: 1 | J16: 3 | K16: 2 | L16: 5 | M16: 5 | N16: 5 | O16: 5 | P16: 4 | Q16: 4 | R16: 4 | S16: 5 | T16: 5 | U16: 4 | V16: 2 | W16: 4 | X16: 5 | Y16: 4 | Z16: 4 | AA16: 4 | AB16: 5 | AC16: 5
A17: C- | B17: 3 | C17: 5 | D17: 2 | E17: 5 | F17: 3 | G17: 3 | H17: 1 | I17: 1 | J17: 4 | K17: 2 | L17: 5 | M17: 4 | N17: 4 | O17: 4 | P17: 5 | Q17: 5 | R17: 5 | S17: 4 | T17: 5 | U17: 5 | V17: 1 | W17: 5 | X17: 4 | Y17: 5 | Z17: 5 | AA17: 5 | AB17: 4 | AC17: 4 | AD17: =AVERAGE(R17:V17) -> 4
B18: 3 | C18: 4 | D18: 2 | E18: 4 | F18: 2 | G18: 2 | H18: 1 | I18: 1 | J18: 5 | K18: 2 | L18: 4 | M18: 2 | N18: 2 | O18: 3 | P18: 4 | Q18: 2 | R18: 4 | S18: 2 | T18: 4 | U18: 4 | V18: 1 | W18: 2 | X18: 2 | Y18: 1 | Z18: 5 | AA18: 4 | AB18: 4 | AC18: 2
A19: D+ | B19: 3 | C19: 3 | D19: 3 | E19: 5 | F19: 3 | G19: 1 | H19: 1 | I19: 4 | J19: 1 | K19: 1 | L19: 5 | M19: 3 | N19: 3 | O19: 4 | P19: 5 | Q19: 3 | R19: 5 | S19: 3 | T19: 5 | U19: 5 | V19: 2 | W19: 3 | X19: 2 | Y19: 2 | Z19: 5 | AA19: 5 | AB19: 5 | AC19: 1 | AD19: =AVERAGE(R19:V19) -> 4
B20: 3 | C20: 2 | D20: 2 | E20: 4 | F20: 4 | G20: 2 | H20: 1 | I20: 3 | J20: 1 | K20: 1 | L20: 4 | M20: 3 | N20: 3 | O20: 5 | P20: 5 | Q20: 4 | R20: 4 | S20: 4 | T20: 4 | U20: 5 | V20: 2 | W20: 3 | X20: 2 | Y20: 2 | Z20: 5 | AA20: 5 | AB20: 5 | AC20: 2
A21: D+ | B21: 3 | C21: 3 | D21: 3 | E21: 4 | F21: 2 | G21: 3 | H21: 1 | I21: 1 | J21: 1 | K21: 1 | L21: 3 | M21: 4 | N21: 3 | O21: 4 | P21: 5 | Q21: 4 | R21: 3 | S21: 5 | T21: 5 | U21: 5 | V21: 1 | W21: 3 | X21: 5 | Y21: 4 | Z21: 1 | AA21: 5 | AB21: 5 | AC21: 1 | AD21: =AVERAGE(R21:V21) -> 3.8
B22: 3 | C22: 4 | D22: 3 | E22: 4 | F22: 2 | G22: 3 | H22: 2 | I22: 2 | J22: 1 | K22: 1 | L22: 3 | M22: 4 | N22: 3 | O22: 4 | P22: 5 | Q22: 4 | R22: 3 | S22: 5 | T22: 5 | U22: 5 | V22: 2 | W22: 3 | X22: 5 | Y22: 4 | Z22: 1 | AA22: 5 | AB22: 5 | AC22: 1
A23: D+ | B23: 3 | C23: 5 | D23: 5 | E23: 5 | F23: 2 | G23: 1 | H23: 2 | I23: 3 | J23: 1 | K23: 1 | L23: 5 | M23: 5 | N23: 4 | O23: 4 | P23: 5 | Q23: 5 | R23: 5 | S23: 4 | T23: 4 | U23: 4 | V23: 2 | W23: 4 | X23: 3 | Y23: 5 | Z23: 4 | AA23: 5 | AB23: 4 | AC23: 5 | AD23: =AVERAGE(R23:V23) -> 3.8
B24: 3 | C24: 5 | D24: 5 | E24: 4 | F24: 2 | G24: 1 | H24: 2 | I24: 2 | J24: 1 | K24: 1 | L24: 4 | M24: 4 | N24: 5 | O24: 4 | P24: 5 | Q24: 5 | R24: 5 | S24: 4 | T24: 4 | U24: 4 | V24: 2 | W24: 5 | X24: 3 | Y24: 5 | Z24: 4 | AA24: 5 | AB24: 4 | AC24: 4
A25: D+ | B25: 3 | C25: 5 | D25: 4 | E25: 5 | F25: 1 | G25: 1 | H25: 1 | I25: 1 | J25: 1 | K25: 1 | L25: 4 | M25: 4 | N25: 2 | O25: 4 | P25: 5 | Q25: 5 | R25: 1 | S25: 5 | T25: 5 | U25: 5 | V25: 1 | W25: 4 | X25: 5 | Y25: 5 | Z25: 5 | AA25: 5 | AB25: 5 | AC25: 4 | AD25: =AVERAGE(R25:V25) -> 3.4
A26: C+ | B26: 2 | C26: 4 | D26: 4 | E26: 5 | F26: 5 | G26: 4 | H26: 1 | I26: 1 | J26: 1 | K26: 1 | L26: 4 | M26: 3 | N26: 4 | O26: 5 | P26: 3 | Q26: 5 | R26: 5 | S26: 4 | T26: 4 | U26: 3 | V26: 4 | W26: 5 | X26: 4 | Y26: 5 | Z26: 4 | AA26: 5 | AB26: 5 | AC26: 5 | AD26: =AVERAGE(R26:V26) -> 4
B27: 2 | C27: 5 | D27: 5 | E27: 4 | F27: 4 | G27: 4 | H27: 1 | I27: 1 | J27: 1 | K27: 1 | L27: 5 | M27: 3 | N27: 4 | O27: 5 | P27: 4 | Q27: 4 | R27: 4 | S27: 5 | T27: 4 | U27: 3 | V27: 4 | W27: 5 | X27: 4 | Y27: 5 | Z27: 4 | AA27: 5 | AB27: 5 | AC27: 5
A28: E | B28: 2 | C28: 5 | D28: 3 | E28: 5 | F28: 3 | G28: 5 | H28: 1 | I28: 2 | J28: 1 | K28: 1 | L28: 5 | M28: 3 | N28: 2 | O28: 5 | P28: 3 | Q28: 5 | R28: 5 | S28: 5 | T28: 5 | U28: 5 | V28: 5 | W28: 5 | X28: 5 | Y28: 5 | Z28: 5 | AA28: 5 | AB28: 5 | AC28: 5 | AD28: =AVERAGE(R28:V28) -> 5
B29: 2 | C29: 4 | D29: 3 | E29: 5 | F29: 3 | G29: 5 | H29: 1 | I29: 2 | J29: 1 | K29: 1 | L29: 4 | M29: 3 | N29: 3 | O29: 4 | P29: 3 | Q29: 5 | R29: 4 | S29: 5 | T29: 4 | U29: 5 | V29: 4 | W29: 5 | X29: 4 | Y29: 5 | Z29: 4 | AA29: 5 | AB29: 4 | AC29: 4
A30: d- | B30: 2 | C30: 5 | D30: 4 | E30: 5 | F30: 4 | G30: 4 | H30: 1 | I30: 4 | J30: 4 | K30: 2 | L30: 4 | M30: 5 | N30: 4 | O30: 4 | P30: 4 | Q30: 5 | R30: 5 | S30: 5 | T30: 5 | U30: 5 | V30: 4 | W30: 5 | X30: 5 | Y30: 5 | Z30: 5 | AA30: 5 | AB30: 5 | AC30: 5 | AD30: =AVERAGE(R30:V30) -> 4.8
B31: 2 | C31: 4 | D31: 4 | E31: 5 | F31: 5 | G31: 5 | H31: 1 | I31: 5 | J31: 4 | K31: 2 | L31: 4 | M31: 5 | N31: 3 | O31: 4 | P31: 4 | Q31: 5 | R31: 5 | S31: 4 | T31: 5 | U31: 5 | V31: 4 | W31: 5 | X31: 5 | Y31: 5 | Z31: 5 | AA31: 5 | AB31: 5 | AC31: 5
A32: c | B32: 2 | C32: 5 | D32: 2 | E32: 5 | F32: 1 | G32: 1 | H32: 1 | I32: 1 | J32: 1 | K32: 1 | L32: 4 | M32: 3 | N32: 3 | O32: 5 | P32: 5 | Q32: 4 | R32: 5 | S32: 5 | T32: 5 | U32: 5 | V32: 5 | W32: 5 | X32: 5 | Y32: 5 | Z32: 5 | AA32: 5 | AB32: 5 | AC32: 5 | AD32: =AVERAGE(R32:V32) -> 5
B33: 2 | C33: 5 | D33: 2 | E33: 5 | F33: 1 | G33: 1 | H33: 1 | I33: 1 | J33: 1 | K33: 1 | L33: 4 | M33: 2 | N33: 3 | O33: 5 | P33: 5 | Q33: 5 | R33: 5 | S33: 5 | T33: 5 | U33: 5 | V33: 5 | W33: 5 | X33: 5 | Y33: 5 | Z33: 5 | AA33: 4 | AB33: 4 | AC33: 5
A34: d- | B34: 2 | C34: 5 | D34: 5 | E34: 3 | F34: 4 | G34: 1 | H34: 2 | I34: 4 | J34: 1 | K34: 4 | L34: 3 | M34: 2 | N34: 3 | O34: 4 | P34: 5 | Q34: 4 | R34: 5 | S34: 5 | T34: 5 | U34: 5 | V34: 1 | W34: 5 | X34: 5 | Y34: 5 | Z34: 5 | AA34: 5 | AB34: 5 | AC34: 5 | AD34: =AVERAGE(R34:V34) -> 4.2
B35: 2 | C35: 4 | D35: 5 | E35: 3 | F35: 4 | G35: 1 | H35: 2 | I35: 4 | J35: 1 | K35: 5 | L35: 2 | M35: 3 | N35: 3 | O35: 4 | P35: 5 | Q35: 4 | R35: 5 | S35: 5 | T35: 5 | U35: 5 | V35: 1 | W35: 5 | X35: 5 | Y35: 5 | Z35: 5 | AA35: 5 | AB35: 5 | AC35: 5
A36: e | B36: 2 | C36: 5 | D36: 3 | E36: 5 | F36: 3 | G36: 4 | H36: 1 | I36: 2 | J36: 3 | K36: 1 | L36: 4 | M36: 3 | N36: 2 | O36: 3 | P36: 3 | Q36: 3 | R36: 5 | S36: 5 | T36: 5 | U36: 5 | V36: 1 | W36: 5 | X36: 5 | Y36: 5 | Z36: 5 | AA36: 5 | AB36: 5 | AC36: 5 | AD36: =AVERAGE(R36:V36) -> 4.2
A37: d | B37: 4 | C37: 5 | D37: 3 | E37: 5 | F37: 1 | G37: 2 | H37: 1 | I37: 3 | J37: 3 | K37: 5 | L37: 2 | M37: 1 | N37: 5 | O37: 5 | P37: 5 | Q37: 4 | R37: 5 | S37: 4 | T37: 3 | U37: 2 | V37: 2 | W37: 5 | X37: 5 | Y37: 5 | Z37: 5 | AA37: 3 | AB37: 5 | AC37: 5 | AD37: =AVERAGE(R37:V37) -> 3.2
B38: 4 | C38: 4 | D38: 2 | E38: 4 | F38: 1 | G38: 2 | H38: 1 | I38: 3 | J38: 3 | K38: 5 | L38: 2 | M38: 1 | N38: 5 | O38: 5 | P38: 5 | Q38: 4 | R38: 5 | S38: 5 | T38: 3 | U38: 2 | V38: 2 | W38: 5 | X38: 5 | Y38: 5 | Z38: 5 | AA38: 3 | AB38: 5 | AC38: 5
A39: e | B39: 4 | C39: 2 | D39: 1 | E39: 5 | F39: 5 | G39: 5 | H39: 1 | I39: 5 | J39: 3 | K39: 5 | L39: 3 | M39: 1 | N39: 1 | O39: 5 | P39: 4 | Q39: 5 | R39: 3 | S39: 5 | T39: 2 | U39: 2 | V39: 1 | W39: 3 | X39: 1 | Y39: 3 | Z39: 5 | AA39: 5 | AB39: 3 | AC39: 3 | AD39: =AVERAGE(R39:V39) -> 2.6
B40: 4 | C40: 3 | D40: 1 | E40: 5 | F40: 5 | G40: 5 | H40: 1 | I40: 4 | J40: 3 | K40: 4 | L40: 3 | M40: 1 | N40: 1 | O40: 5 | P40: 4 | Q40: 5 | R40: 2 | S40: 5 | T40: 2 | U40: 2 | V40: 1 | W40: 4 | X40: 2 | Y40: 3 | Z40: 5 | AA40: 5 | AB40: 3 | AC40: 3
...

Sheet Working sheet
A1: Performance | B1: Stream | C1: I listen attentively | D1: Actively participate | E1: I want good grades | F1: Struggle to understand | G1: Math scares me | H1: Don't like or enjoy math | I1: mind goes blank | J1: I feel insecure | K1: Makes me uncomfortable, restless, impatient | L1: I do assignments regularly | M1: I put more effort in difficult assignments | N1: I spend time studying maths | O1: I study and prepare for tests | P1: I put in effort to improve my performance | Q1: Studies come first in my life | R1: Clearly explains new concepts | S1: Encourages us to ask questions | T1: Explains concepts in different ways | U1: Provides real-world applications | V1: Makes me feel ocmfortable to make mistakes | W1: Provides extra help to struggling students | X1: Sets clear explectations | Y1: Provides constructive feedback | Z1: Believes we all can perform well | AA1: Is available outside class time | AB1: Provides clear instructions for assignments | AC1: Explains progress in areas we are lacking.
A2: 67 | B2: 1 | C2: 4 | D2: 5 | E2: 4 | F2: 4 | G2: 4 | H2: 4 | I2: 1 | J2: 2 | K2: 1 | L2: 4 | M2: 4 | N2: 4 | O2: 4 | P2: 4 | Q2: 4 | R2: 4 | S2: 4 | T2: 4 | U2: 1 | V2: 4 | W2: 5 | X2: 2 | Y2: 4 | Z2: 5 | AA2: 4 | AB2: 4 | AC2: 5 | AD2: =AVERAGE(R2:V2) -> 3.4
A3: 56 | B3: 1 | C3: 5 | D3: 4 | E3: 5 | F3: 5 | G3: 4 | H3: 3 | I3: 2 | J3: 1 | K3: 1 | L3: 4 | M3: 5 | N3: 3 | O3: 4 | P3: 5 | Q3: 5 | R3: 5 | S3: 5 | T3: 3 | U3: 2 | V3: 5 | W3: 4 | X3: 3 | Y3: 5 | Z3: 5 | AA3: 4 | AB3: 5 | AC3: 4 | AD3: =AVERAGE(R3:V3) -> 4
A4: 43 | B4: 1 | C4: 4 | D4: 3 | E4: 4 | F4: 4 | G4: 4 | H4: 1 | I4: 2 | J4: 1 | K4: 1 | L4: 3 | M4: 3 | N4: 2 | O4: 3 | P4: 4 | Q4: 5 | R4: 4 | S4: 5 | T4: 5 | U4: 3 | V4: 4 | W4: 5 | X4: 1 | Y4: 4 | Z4: 4 | AA4: 4 | AB4: 4 | AC4: 4
A5: 38 | B5: 1 | C5: 4 | D5: 3 | E5: 4 | F5: 4 | G5: 4 | H5: 1 | I5: 1 | J5: 1 | K5: 1 | L5: 4 | M5: 4 | N5: 3 | O5: 4 | P5: 4 | Q5: 4 | R5: 5 | S5: 5 | T5: 4 | U5: 5 | V5: 1 | W5: 5 | X5: 5 | Y5: 5 | Z5: 5 | AA5: 5 | AB5: 5 | AC5: 5 | AD5: =AVERAGE(R5:V5) -> 4
A6: 28 | B6: 1 | C6: 5 | D6: 3 | E6: 4 | F6: 4 | G6: 4 | H6: 1 | I6: 3 | J6: 1 | K6: 2 | L6: 5 | M6: 4 | N6: 2 | O6: 4 | P6: 5 | Q6: 4 | R6: 4 | S6: 5 | T6: 5 | U6: 5 | V6: 1 | W6: 5 | X6: 5 | Y6: 5 | Z6: 5 | AA6: 4 | AB6: 5 | AC6: 5
A7: 54 | B7: 1 | C7: 4 | D7: 2 | E7: 5 | F7: 4 | G7: 4 | H7: 2 | I7: 2 | J7: 2 | K7: 2 | L7: 4 | M7: 5 | N7: 3 | O7: 5 | P7: 4 | Q7: 3 | R7: 3 | S7: 5 | T7: 5 | U7: 5 | V7: 2 | W7: 5 | X7: 5 | Y7: 4 | Z7: 5 | AA7: 4 | AB7: 5 | AC7: 5
A8: 48 | B8: 1 | C8: 4 | D8: 3 | E8: 5 | F8: 3 | G8: 4 | H8: 1 | I8: 2 | J8: 3 | K8: 3 | L8: 4 | M8: 3 | N8: 2 | O8: 3 | P8: 5 | Q8: 4 | R8: 2 | S8: 5 | T8: 5 | U8: 5 | V8: 2 | W8: 3 | X8: 2 | Y8: 3 | Z8: 5 | AA8: 5 | AB8: 5 | AC8: 5 | AD8: =AVERAGE(R8:V8) -> 3.8
A9: 47 | B9: 1 | C9: 5 | D9: 3 | E9: 4 | F9: 3 | G9: 5 | H9: 2 | I9: 1 | J9: 2 | K9: 2 | L9: 4 | M9: 3 | N9: 2 | O9: 3 | P9: 4 | Q9: 5 | R9: 1 | S9: 4 | T9: 4 | U9: 5 | V9: 3 | W9: 3 | X9: 2 | Y9: 3 | Z9: 4 | AA9: 4 | AB9: 5 | AC9: 5
A10: 39 | B10: 1 | C10: 4 | D10: 2 | E10: 5 | F10: 5 | G10: 4 | H10: 1 | I10: 2 | J10: 1 | K10: 1 | L10: 4 | M10: 5 | N10: 5 | O10: 5 | P10: 5 | Q10: 4 | R10: 5 | S10: 5 | T10: 5 | U10: 5 | V10: 5 | W10: 5 | X10: 5 | Y10: 5 | Z10: 5 | AA10: 5 | AB10: 5 | AC10: 5 | AD10: =AVERAGE(R10:V10) -> 5
A11: 36 | B11: 1 | C11: 5 | D11: 3 | E11: 5 | F11: 5 | G11: 4 | H11: 1 | I11: 2 | J11: 2 | K11: 2 | L11: 4 | M11: 5 | N11: 4 | O11: 5 | P11: 5 | Q11: 4 | R11: 5 | S11: 5 | T11: 5 | U11: 5 | V11: 5 | W11: 5 | X11: 5 | Y11: 4 | Z11: 5 | AA11: 5 | AB11: 5 | AC11: 5
A12: 34 | B12: 1 | C12: 4 | D12: 2 | E12: 4 | F12: 5 | G12: 4 | H12: 1 | I12: 1 | J12: 1 | K12: 1 | L12: 4 | M12: 5 | N12: 4 | O12: 4 | P12: 4 | Q12: 4 | R12: 5 | S12: 5 | T12: 5 | U12: 5 | V12: 4 | W12: 5 | X12: 4 | Y12: 5 | Z12: 5 | AA12: 5 | AB12: 5 | AC12: 5
A13: 32 | B13: 1 | C13: 4 | D13: 4 | E13: 4 | F13: 4 | G13: 1 | H13: 1 | I13: 1 | J13: 1 | K13: 1 | L13: 4 | M13: 4 | N13: 4 | O13: 4 | P13: 4 | Q13: 4 | R13: 4 | S13: 5 | T13: 5 | U13: 4 | V13: 1 | W13: 5 | X13: 5 | Y13: 4 | Z13: 5 | AA13: 5 | AB13: 5 | AC13: 5 | AD13: =AVERAGE(R13:V13) -> 3.8
A14: 55 | B14: 3 | C14: 4 | D14: 3 | E14: 5 | F14: 2 | G14: 3 | H14: 1 | I14: 3 | J14: 3 | K14: 1 | L14: 4 | M14: 4 | N14: 4 | O14: 4 | P14: 4 | Q14: 4 | R14: 5 | S14: 5 | T14: 5 | U14: 5 | V14: 1 | W14: 1 | X14: 2 | Y14: 2 | Z14: 2 | AA14: 3 | AB14: 2 | AC14: 5 | AD14: =AVERAGE(R14:V14) -> 4.2
A15: 43 | B15: 3 | C15: 5 | D15: 2 | E15: 5 | F15: 3 | G15: 3 | H15: 1 | I15: 1 | J15: 3 | K15: 2 | L15: 5 | M15: 5 | N15: 5 | O15: 5 | P15: 4 | Q15: 4 | R15: 4 | S15: 5 | T15: 5 | U15: 4 | V15: 2 | W15: 4 | X15: 5 | Y15: 4 | Z15: 4 | AA15: 4 | AB15: 5 | AC15: 5
A16: 55 | B16: 3 | C16: 5 | D16: 2 | E16: 5 | F16: 3 | G16: 3 | H16: 1 | I16: 1 | J16: 4 | K16: 2 | L16: 5 | M16: 4 | N16: 4 | O16: 4 | P16: 5 | Q16: 5 | R16: 5 | S16: 4 | T16: 5 | U16: 5 | V16: 1 | W16: 5 | X16: 4 | Y16: 5 | Z16: 5 | AA16: 5 | AB16: 4 | AC16: 4 | AD16: =AVERAGE(R16:V16) -> 4
A17: 45 | B17: 3 | C17: 4 | D17: 2 | E17: 4 | F17: 2 | G17: 2 | H17: 1 | I17: 1 | J17: 5 | K17: 2 | L17: 4 | M17: 2 | N17: 2 | O17: 3 | P17: 4 | Q17: 2 | R17: 4 | S17: 2 | T17: 4 | U17: 4 | V17: 1 | W17: 2 | X17: 2 | Y17: 1 | Z17: 5 | AA17: 4 | AB17: 4 | AC17: 2
A18: 50 | B18: 3 | C18: 3 | D18: 3 | E18: 5 | F18: 3 | G18: 1 | H18: 1 | I18: 4 | J18: 1 | K18: 1 | L18: 5 | M18: 3 | N18: 3 | O18: 4 | P18: 5 | Q18: 3 | R18: 5 | S18: 3 | T18: 5 | U18: 5 | V18: 2 | W18: 3 | X18: 2 | Y18: 2 | Z18: 5 | AA18: 5 | AB18: 5 | AC18: 1 | AD18: =AVERAGE(R18:V18) -> 4
A19: 46 | B19: 3 | C19: 2 | D19: 2 | E19: 4 | F19: 4 | G19: 2 | H19: 1 | I19: 3 | J19: 1 | K19: 1 | L19: 4 | M19: 3 | N19: 3 | O19: 5 | P19: 5 | Q19: 4 | R19: 4 | S19: 4 | T19: 4 | U19: 5 | V19: 2 | W19: 3 | X19: 2 | Y19: 2 | Z19: 5 | AA19: 5 | AB19: 5 | AC19: 2
A20: 50 | B20: 3 | C20: 3 | D20: 3 | E20: 4 | F20: 2 | G20: 3 | H20: 1 | I20: 1 | J20: 1 | K20: 1 | L20: 3 | M20: 4 | N20: 3 | O20: 4 | P20: 5 | Q20: 4 | R20: 3 | S20: 5 | T20: 5 | U20: 5 | V20: 1 | W20: 3 | X20: 5 | Y20: 4 | Z20: 1 | AA20: 5 | AB20: 5 | AC20: 1 | AD20: =AVERAGE(R20:V20) -> 3.8
A21: 43 | B21: 3 | C21: 4 | D21: 3 | E21: 4 | F21: 2 | G21: 3 | H21: 2 | I21: 2 | J21: 1 | K21: 1 | L21: 3 | M21: 4 | N21: 3 | O21: 4 | P21: 5 | Q21: 4 | R21: 3 | S21: 5 | T21: 5 | U21: 5 | V21: 2 | W21: 3 | X21: 5 | Y21: 4 | Z21: 1 | AA21: 5 | AB21: 5 | AC21: 1
A22: 50 | B22: 3 | C22: 5 | D22: 5 | E22: 5 | F22: 2 | G22: 1 | H22: 2 | I22: 3 | J22: 1 | K22: 1 | L22: 5 | M22: 5 | N22: 4 | O22: 4 | P22: 5 | Q22: 5 | R22: 5 | S22: 4 | T22: 4 | U22: 4 | V22: 2 | W22: 4 | X22: 3 | Y22: 5 | Z22: 4 | AA22: 5 | AB22: 4 | AC22: 5 | AD22: =AVERAGE(R22:V22) -> 3.8
A23: 40 | B23: 3 | C23: 5 | D23: 5 | E23: 4 | F23: 2 | G23: 1 | H23: 2 | I23: 2 | J23: 1 | K23: 1 | L23: 4 | M23: 4 | N23: 5 | O23: 4 | P23: 5 | Q23: 5 | R23: 5 | S23: 4 | T23: 4 | U23: 4 | V23: 2 | W23: 5 | X23: 3 | Y23: 5 | Z23: 4 | AA23: 5 | AB23: 4 | AC23: 4
A24: 50 | B24: 3 | C24: 5 | D24: 4 | E24: 5 | F24: 1 | G24: 1 | H24: 1 | I24: 1 | J24: 1 | K24: 1 | L24: 4 | M24: 4 | N24: 2 | O24: 4 | P24: 5 | Q24: 5 | R24: 1 | S24: 5 | T24: 5 | U24: 5 | V24: 1 | W24: 4 | X24: 5 | Y24: 5 | Z24: 5 | AA24: 5 | AB24: 5 | AC24: 4 | AD24: =AVERAGE(R24:V24) -> 3.4
A25: 70 | B25: 2 | C25: 4 | D25: 4 | E25: 5 | F25: 5 | G25: 4 | H25: 1 | I25: 1 | J25: 1 | K25: 1 | L25: 4 | M25: 3 | N25: 4 | O25: 5 | P25: 3 | Q25: 5 | R25: 5 | S25: 4 | T25: 4 | U25: 3 | V25: 4 | W25: 5 | X25: 4 | Y25: 5 | Z25: 4 | AA25: 5 | AB25: 5 | AC25: 5 | AD25: =AVERAGE(R25:V25) -> 4
A26: 63 | B26: 2 | C26: 5 | D26: 5 | E26: 4 | F26: 4 | G26: 4 | H26: 1 | I26: 1 | J26: 1 | K26: 1 | L26: 5 | M26: 3 | N26: 4 | O26: 5 | P26: 4 | Q26: 4 | R26: 4 | S26: 5 | T26: 4 | U26: 3 | V26: 4 | W26: 5 | X26: 4 | Y26: 5 | Z26: 4 | AA26: 5 | AB26: 5 | AC26: 5
A27: 30 | B27: 2 | C27: 5 | D27: 3 | E27: 5 | F27: 3 | G27: 5 | H27: 1 | I27: 2 | J27: 1 | K27: 1 | L27: 5 | M27: 3 | N27: 2 | O27: 5 | P27: 3 | Q27: 5 | R27: 5 | S27: 5 | T27: 5 | U27: 5 | V27: 5 | W27: 5 | X27: 5 | Y27: 5 | Z27: 5 | AA27: 5 | AB27: 5 | AC27: 5 | AD27: =AVERAGE(R27:V27) -> 5
A28: 32 | B28: 2 | C28: 4 | D28: 3 | E28: 5 | F28: 3 | G28: 5 | H28: 1 | I28: 2 | J28: 1 | K28: 1 | L28: 4 | M28: 3 | N28: 3 | O28: 4 | P28: 3 | Q28: 5 | R28: 4 | S28: 5 | T28: 4 | U28: 5 | V28: 4 | W28: 5 | X28: 4 | Y28: 5 | Z28: 4 | AA28: 5 | AB28: 4 | AC28: 4
A29: 39 | B29: 2 | C29: 5 | D29: 4 | E29: 5 | F29: 4 | G29: 4 | H29: 1 | I29: 4 | J29: 4 | K29: 2 | L29: 4 | M29: 5 | N29: 4 | O29: 4 | P29: 4 | Q29: 5 | R29: 5 | S29: 5 | T29: 5 | U29: 5 | V29: 4 | W29: 5 | X29: 5 | Y29: 5 | Z29: 5 | AA29: 5 | AB29: 5 | AC29: 5 | AD29: =AVERAGE(R29:V29) -> 4.8
A30: 32 | B30: 2 | C30: 4 | D30: 4 | E30: 5 | F30: 5 | G30: 5 | H30: 1 | I30: 5 | J30: 4 | K30: 2 | L30: 4 | M30: 5 | N30: 3 | O30: 4 | P30: 4 | Q30: 5 | R30: 5 | S30: 4 | T30: 5 | U30: 5 | V30: 4 | W30: 5 | X30: 5 | Y30: 5 | Z30: 5 | AA30: 5 | AB30: 5 | AC30: 5
A31: 65 | B31: 2 | C31: 5 | D31: 2 | E31: 5 | F31: 1 | G31: 1 | H31: 1 | I31: 1 | J31: 1 | K31: 1 | L31: 4 | M31: 3 | N31: 3 | O31: 5 | P31: 5 | Q31: 4 | R31: 5 | S31: 5 | T31: 5 | U31: 5 | V31: 5 | W31: 5 | X31: 5 | Y31: 5 | Z31: 5 | AA31: 5 | AB31: 5 | AC31: 5 | AD31: =AVERAGE(R31:V31) -> 5
A32: 58 | B32: 2 | C32: 5 | D32: 2 | E32: 5 | F32: 1 | G32: 1 | H32: 1 | I32: 1 | J32: 1 | K32: 1 | L32: 4 | M32: 2 | N32: 3 | O32: 5 | P32: 5 | Q32: 5 | R32: 5 | S32: 5 | T32: 5 | U32: 5 | V32: 5 | W32: 5 | X32: 5 | Y32: 5 | Z32: 5 | AA32: 4 | AB32: 4 | AC32: 5
A33: 38 | B33: 2 | C33: 5 | D33: 5 | E33: 3 | F33: 4 | G33: 1 | H33: 2 | I33: 4 | J33: 1 | K33: 4 | L33: 3 | M33: 2 | N33: 3 | O33: 4 | P33: 5 | Q33: 4 | R33: 5 | S33: 5 | T33: 5 | U33: 5 | V33: 1 | W33: 5 | X33: 5 | Y33: 5 | Z33: 5 | AA33: 5 | AB33: 5 | AC33: 5 | AD33: =AVERAGE(R33:V33) -> 4.2
A34: 36 | B34: 2 | C34: 4 | D34: 5 | E34: 3 | F34: 4 | G34: 1 | H34: 2 | I34: 4 | J34: 1 | K34: 5 | L34: 2 | M34: 3 | N34: 3 | O34: 4 | P34: 5 | Q34: 4 | R34: 5 | S34: 5 | T34: 5 | U34: 5 | V34: 1 | W34: 5 | X34: 5 | Y34: 5 | Z34: 5 | AA34: 5 | AB34: 5 | AC34: 5
A35: 24 | B35: 2 | C35: 5 | D35: 3 | E35: 5 | F35: 3 | G35: 4 | H35: 1 | I35: 2 | J35: 3 | K35: 1 | L35: 4 | M35: 3 | N35: 2 | O35: 3 | P35: 3 | Q35: 3 | R35: 5 | S35: 5 | T35: 5 | U35: 5 | V35: 1 | W35: 5 | X35: 5 | Y35: 5 | Z35: 5 | AA35: 5 | AB35: 5 | AC35: 5 | AD35: =AVERAGE(R35:V35) -> 4.2
A36: 44 | B36: 4 | C36: 5 | D36: 3 | E36: 5 | F36: 1 | G36: 2 | H36: 1 | I36: 3 | J36: 3 | K36: 5 | L36: 2 | M36: 1 | N36: 5 | O36: 5 | P36: 5 | Q36: 4 | R36: 5 | S36: 4 | T36: 3 | U36: 2 | V36: 2 | W36: 5 | X36: 5 | Y36: 5 | Z36: 5 | AA36: 3 | AB36: 5 | AC36: 5 | AD36: =AVERAGE(R36:V36) -> 3.2
A37: 41 | B37: 4 | C37: 4 | D37: 2 | E37: 4 | F37: 1 | G37: 2 | H37: 1 | I37: 3 | J37: 3 | K37: 5 | L37: 2 | M37: 1 | N37: 5 | O37: 5 | P37: 5 | Q37: 4 | R37: 5 | S37: 5 | T37: 3 | U37: 2 | V37: 2 | W37: 5 | X37: 5 | Y37: 5 | Z37: 5 | AA37: 3 | AB37: 5 | AC37: 5
A38: 30 | B38: 4 | C38: 2 | D38: 1 | E38: 5 | F38: 5 | G38: 5 | H38: 1 | I38: 5 | J38: 3 | K38: 5 | L38: 3 | M38: 1 | N38: 1 | O38: 5 | P38: 4 | Q38: 5 | R38: 3 | S38: 5 | T38: 2 | U38: 2 | V38: 1 | W38: 3 | X38: 1 | Y38: 3 | Z38: 5 | AA38: 5 | AB38: 3 | AC38: 3 | AD38: =AVERAGE(R38:V38) -> 2.6
A39: 28 | B39: 4 | C39: 3 | D39: 1 | E39: 5 | F39: 5 | G39: 5 | H39: 1 | I39: 4 | J39: 3 | K39: 4 | L39: 3 | M39: 1 | N39: 1 | O39: 5 | P39: 4 | Q39: 5 | R39: 2 | S39: 5 | T39: 2 | U39: 2 | V39: 1 | W39: 4 | X39: 2 | Y39: 3 | Z39: 5 | AA39: 5 | AB39: 3 | AC39: 3
A40: 43 | B40: 4 | C40: 2 | D40: 1 | E40: 5 | F40: 5 | G40: 5 | H40: 1 | I40: 4 | J40: 3 | K40: 1 | L40: 2 | M40: 2 | N40: 3 | O40: 5 | P40: 5 | Q40: 5 | R40: 3 | S40: 5 | T40: 5 | U40: 1 | V40: 5 | W40: 3 | X40: 4 | Y40: 3 | Z40: 5 | AA40: 5 | AB40: 5 | AC40: 4 | AD40: =AVERAGE(R40:V40) -> 3.8
...

Sheet Tables
A3: Row Labels | B3: Average of Student Study Habits | C3: Average of Student Interest | D3: Average of Student Attitude
A4: Stream A | B4: 3.9861111 | C4: 3.9444444 | D4: 2.375
A5: Stream B | B5: 3.8333333 | C5: 4.2727273 | D5: 2.2878788
A6: Stream C | B6: 4.0606061 | C6: 3.9090909 | D6: 1.8333333
A7: Stream D | B7: 3.8636364 | C7: 3.7878788 | D7: 2.5
A8: Stream E | B8: 4.0454545 | C8: 3.8787879 | D8: 1.969697
A9: Grand Total | B9: 3.9583333 | C9: 3.9583333 | D9: 2.1964286
A14: Row Labels | B14: Average of Teacher Teaching style | C14: Average of Teacher Expectation and Support | D14: Average of Teacher Availability & Communication
A15: Stream A | B15: 4.1166667 | C15: 4.3333333 | D15: 4.7222222
A16: Stream B | B16: 4.4909091 | C16: 4.8636364 | D16: 4.8787879
A17: Stream C | B17: 3.8 | C17: 3.5227273 | D17: 4.030303
A18: Stream D | B18: 3.6727273 | C18: 4.3181818 | D18: 4.3030303
A19: Stream E | B19: 4.2363636 | C19: 4.8863636 | D19: 4.7575758
A20: (blank)
A21: Grand Total | B21: 4.0642857 | C21: 4.3839286 | D21: 4.5416667

Sheet Compiled Data
A1: Performance | B1: Stream | C1: Student Interest | D1: Student Attitude | E1: Student Study Habits | F1: Teacher Teaching style | G1: Teacher Expectation and Support | H1: Teacher Availability & Communication
A2: 67 | B2: Stream A | C2: =AVERAGE('Working sheet'!C2:E2) -> 4.3333333 | D2: =AVERAGE('Working sheet'!F2:K2) -> 2.6666667 | E2: =AVERAGE('Working sheet'!L2:Q2) -> 4 | F2: =AVERAGE('Working sheet'!R2:V2) -> 3.4 | G2: =AVERAGE('Working sheet'!W2:Z2) -> 4 | H2: =AVERAGE('Working sheet'!AA2:AC2) -> 4.3333333
A3: 56 | B3: Stream A | C3: =AVERAGE('Working sheet'!C3:E3) -> 4.6666667 | D3: =AVERAGE('Working sheet'!F3:K3) -> 2.6666667 | E3: =AVERAGE('Working sheet'!L3:Q3) -> 4.3333333 | F3: =AVERAGE('Working sheet'!R3:V3) -> 4 | G3: =AVERAGE('Working sheet'!W3:Z3) -> 4.25 | H3: =AVERAGE('Working sheet'!AA3:AC3) -> 4.3333333
A4: 43 | B4: Stream A | C4: =AVERAGE('Working sheet'!C4:E4) -> 3.6666667 | D4: =AVERAGE('Working sheet'!F4:K4) -> 2.1666667 | E4: =AVERAGE('Working sheet'!L4:Q4) -> 3.3333333 | F4: =AVERAGE('Working sheet'!R4:V4) -> 4.2 | G4: =AVERAGE('Working sheet'!W4:Z4) -> 3.5 | H4: =AVERAGE('Working sheet'!AA4:AC4) -> 4
A5: 38 | B5: Stream A | C5: =AVERAGE('Working sheet'!C5:E5) -> 3.6666667 | D5: =AVERAGE('Working sheet'!F5:K5) -> 2 | E5: =AVERAGE('Working sheet'!L5:Q5) -> 3.8333333 | F5: =AVERAGE('Working sheet'!R5:V5) -> 4 | G5: =AVERAGE('Working sheet'!W5:Z5) -> 5 | H5: =AVERAGE('Working sheet'!AA5:AC5) -> 5
A6: 28 | B6: Stream A | C6: =AVERAGE('Working sheet'!C6:E6) -> 4 | D6: =AVERAGE('Working sheet'!F6:K6) -> 2.5 | E6: =AVERAGE('Working sheet'!L6:Q6) -> 4 | F6: =AVERAGE('Working sheet'!R6:V6) -> 4 | G6: =AVERAGE('Working sheet'!W6:Z6) -> 5 | H6: =AVERAGE('Working sheet'!AA6:AC6) -> 4.6666667
A7: 54 | B7: Stream A | C7: =AVERAGE('Working sheet'!C7:E7) -> 3.6666667 | D7: =AVERAGE('Working sheet'!F7:K7) -> 2.6666667 | E7: =AVERAGE('Working sheet'!L7:Q7) -> 4 | F7: =AVERAGE('Working sheet'!R7:V7) -> 4 | G7: =AVERAGE('Working sheet'!W7:Z7) -> 4.75 | H7: =AVERAGE('Working sheet'!AA7:AC7) -> 4.6666667
A8: 48 | B8: Stream A | C8: =AVERAGE('Working sheet'!C8:E8) -> 4 | D8: =AVERAGE('Working sheet'!F8:K8) -> 2.6666667 | E8: =AVERAGE('Working sheet'!L8:Q8) -> 3.5 | F8: =AVERAGE('Working sheet'!R8:V8) -> 3.8 | G8: =AVERAGE('Working sheet'!W8:Z8) -> 3.25 | H8: =AVERAGE('Working sheet'!AA8:AC8) -> 5
A9: 47 | B9: Stream A | C9: =AVERAGE('Working sheet'!C9:E9) -> 4 | D9: =AVERAGE('Working sheet'!F9:K9) -> 2.5 | E9: =AVERAGE('Working sheet'!L9:Q9) -> 3.5 | F9: =AVERAGE('Working sheet'!R9:V9) -> 3.4 | G9: =AVERAGE('Working sheet'!W9:Z9) -> 3 | H9: =AVERAGE('Working sheet'!AA9:AC9) -> 4.6666667
A10: 39 | B10: Stream A | C10: =AVERAGE('Working sheet'!C10:E10) -> 3.6666667 | D10: =AVERAGE('Working sheet'!F10:K10) -> 2.3333333 | E10: =AVERAGE('Working sheet'!L10:Q10) -> 4.6666667 | F10: =AVERAGE('Working sheet'!R10:V10) -> 5 | G10: =AVERAGE('Working sheet'!W10:Z10) -> 5 | H10: =AVERAGE('Working sheet'!AA10:AC10) -> 5
A11: 36 | B11: Stream A | C11: =AVERAGE('Working sheet'!C11:E11) -> 4.3333333 | D11: =AVERAGE('Working sheet'!F11:K11) -> 2.6666667 | E11: =AVERAGE('Working sheet'!L11:Q11) -> 4.5 | F11: =AVERAGE('Working sheet'!R11:V11) -> 5 | G11: =AVERAGE('Working sheet'!W11:Z11) -> 4.75 | H11: =AVERAGE('Working sheet'!AA11:AC11) -> 5
A12: 34 | B12: Stream A | C12: =AVERAGE('Working sheet'!C12:E12) -> 3.3333333 | D12: =AVERAGE('Working sheet'!F12:K12) -> 2.1666667 | E12: =AVERAGE('Working sheet'!L12:Q12) -> 4.1666667 | F12: =AVERAGE('Working sheet'!R12:V12) -> 4.8 | G12: =AVERAGE('Working sheet'!W12:Z12) -> 4.75 | H12: =AVERAGE('Working sheet'!AA12:AC12) -> 5
A13: 32 | B13: Stream A | C13: =AVERAGE('Working sheet'!C13:E13) -> 4 | D13: =AVERAGE('Working sheet'!F13:K13) -> 1.5 | E13: =AVERAGE('Working sheet'!L13:Q13) -> 4 | F13: =AVERAGE('Working sheet'!R13:V13) -> 3.8 | G13: =AVERAGE('Working sheet'!W13:Z13) -> 4.75 | H13: =AVERAGE('Working sheet'!AA13:AC13) -> 5
... A57: 18 | B57: Stream E | C57: =AVERAGE('Working sheet'!C57:E57) -> 4.3333333 | D57: =AVERAGE('Working sheet'!F57:K57) -> 2 | E57: =AVERAGE('Working sheet'!L57:Q57) -> 3.8333333 | F57: =AVERAGE('Working sheet'!R57:V57) -> 4.2 | G57: =AVERAGE('Working sheet'!W57:Z57) -> 4.75 | H57: =AVERAGE('Working sheet'!AA57:AC57) -> 5

Sheet Charts
A2: Row Labels | B2: Teacher Teaching style | C2: Teacher Expectation and Support | D2: Teacher Availability & Communication
A3: Stream A | B3: 4.1166667 | C3: 4.3333333 | D3: 4.7222222
A4: Stream B | B4: 4.4909091 | C4: 4.8636364 | D4: 4.8787879
A5: Stream C | B5: 3.8 | C5: 3.5227273 | D5: 4.030303
A6: Stream D | B6: 3.6727273 | C6: 4.3181818 | D6: 4.3030303
A7: Stream E | B7: 4.2363636 | C7: 4.8863636 | D7: 4.7575758
A11: Row Labels | B11: Student Study Habits | C11: Student Interest | D11: Student Attitude
A12: Stream A | B12: 3.9861111 | C12: 3.9444444 | D12: 2.375
A13: Stream B | B13: 3.8333333 | C13: 4.2727273 | D13: 2.2878788
A14: Stream C | B14: 4.0606061 | C14: 3.9090909 | D14: 1.8333333
A15: Stream D | B15: 3.8636364 | C15: 3.7878788 | D15: 2.5
A16: Stream E | B16: 4.0454545 | C16: 3.8787879 | D16: 1.969697
